<?xml version="1.0"?>

<robot name="jetPR">

  <link name="base_link">
    <pose>0 0 0 0 0 0</pose>
    <!--<inertial>
      <mass value="5.0"/>
      <origin xyz="0.0 0 0.1" rpy=" 0 0 0"/>
      <inertia ixx="0.1208" ixy="0.0" ixz="0.0" iyy="0.1208" iyz="0.0" izz="0.033"/>
    </inertial>
    </inertial>

    <collision name='collision'>
      <geometry>
        <box size=".2 .2 .5"/>
      </geometry>
    </collision> 

     -->
    <visual name='chassis_visual'>
      <origin xyz="0 0 0.3" rpy=" 0 0 0"/>
      <geometry>
        <box size=".2 .3 .5"/>
      </geometry>
    </visual>
  </link>
  
  <link name="left_wheel">
    <!--origin xyz="0.1 0.13 0.1" rpy="0 1.5707 1.5707" 
    <inertial>
      <origin xyz="0 0 0" rpy="0 1.5707 1.5707"/>
      <mass value="5"/>
      <inertia
        ixx=".1" ixy="0.0" ixz="0.0"
        iyy=".1" iyz="0.0"
        izz=".1"/>
    </inertial>
    <collision name="collision">
      <origin xyz="0 0 0" rpy="0 1.5707 1.5707"/>
      <geometry>
        <cylinder radius="0.1" length="0.05"/>
      </geometry>
    </collision>
    /-->
    <visual name="left_wheel_visual">
      <origin xyz="0 0 0" rpy="0 1.5707 1.5707"/>
      <geometry>
        <cylinder radius="0.1" length="0.05"/>
      </geometry>
    </visual>
    
  </link>
  
  <link name="right_wheel">
     <!--origin xyz="0.1 -0.13 0.1" rpy="0 1.5707 1.5707"/
     <collision name="collision">
      <origin xyz="0 0 0" rpy="0 1.5707 1.5707"/>
      <geometry>
        <cylinder radius="0.1" length="0.05"/>
      </geometry>
    </collision> <inertial>
      <origin xyz="0 0 0" rpy="0 1.5707 1.5707"/>
      <mass value="5"/>
      <inertia
        ixx=".1" ixy="0.0" ixz="0.0"
        iyy=".1" iyz="0.0"
        izz=".1"/>
    </inertial>-->
    
    <visual name="right_wheel_visual">
      <origin xyz="0 0 0" rpy="0 1.5707 1.5707"/>
      <geometry>
        <cylinder radius="0.1" length="0.05"/>
      </geometry>
    </visual>
  </link>

  <joint type="continuous" name="left_wheel_hinge">
    <origin xyz="0 0.175 0.1" rpy="0 0 0"/>
    <!--origin xyz="0.1 0.13 0" rpy="0 1.5707 1.5707"/-->
    <child link="left_wheel"/>
    <parent link="base_link"/>
    <axis xyz="0 1 0" rpy="0 0 0"/>
  </joint>

  <joint type="continuous" name="right_wheel_hinge">
    <origin xyz="0 -0.175 0.1" rpy="0 0 0"/>
    <!--origin xyz="0.1 -0.13 0" rpy="0 1.5707 1.5707"/-->
    <child link="right_wheel"/>
    <parent link="base_link"/>
    <axis xyz="0 1 0" rpy="0 0 0"/>
  </joint>

</robot>
